Workbook

Sheet Summary
A1: SLIMS gap analysis — FRD-GSL-001 v1.0 against the current build
A2: Assessed 2026-09-18 · static code review of every requirement + live acceptance run · all figures are formulas over the other sheets
A4: Headline | B4: Requirements | C4: Met | D4: Partially met | E4: Not met | F4: Readiness | G4: Must-have readiness | I4: Acceptance tests (30) | J4: Count
A5: All FRD requirements | B5: =COUNTA('Gap Register'!$G$5:$G$126) -> 122 | C5: =COUNTIF('Gap Register'!$G$5:$G$126,"Met") -> 72 | D5: =COUNTIF('Gap Register'!$G$5:$G$126,"Partially met") -> 50 | E5: =COUNTIF('Gap Register'!$G$5:$G$126,"Not met") -> 0 | F5: =IFERROR((C5+Legend!$B$34*D5)/B5,0) -> 0.79508197 | G5: =IFERROR((COUNTIFS('Gap Register'!$E$5:$E$126,"M",'Gap Register'!$G$5:$G$126,"Met")+Legend!$B$34*COUNTIFS('Gap Register'!$E$5:$E$126,"M",'Gap Register'!$G$5:$G$126,"Partially met"))/COUNTIF('Gap Register'!$E$5:$E$126,"M"),0) -> 0.77227723 | I5: PASS | J5: =COUNTIF('Test Results'!$F$5:$F$34,"PASS") -> 21
A6: Readiness weights a Partially met requirement at the value set on the Legend sheet. | I6: PASS* | J6: =COUNTIF('Test Results'!$F$5:$F$34,"PASS~*") -> 5
I7: PARTIAL | J7: =COUNTIF('Test Results'!$F$5:$F$34,"PARTIAL") -> 4
A8: Module | B8: Requirements | C8: Met | D8: Partially met | E8: Not met | F8: % met | G8: Readiness | I8: NOT BUILT | J8: =COUNTIF('Test Results'!$F$5:$F$34,"NOT BUILT") -> 0
A9: Master Data | B9: =COUNTIF('Gap Register'!$B$5:$B$126,A9) -> 20 | C9: =COUNTIFS('Gap Register'!$B$5:$B$126,$A9,'Gap Register'!$G$5:$G$126,"Met") -> 10 | D9: =COUNTIFS('Gap Register'!$B$5:$B$126,$A9,'Gap Register'!$G$5:$G$126,"Partially met") -> 10 | E9: =COUNTIFS('Gap Register'!$B$5:$B$126,$A9,'Gap Register'!$G$5:$G$126,"Not met") -> 0 | F9: =IFERROR(C9/B9,0) -> 0.5 | G9: =IFERROR((C9+Legend!$B$34*D9)/B9,0) -> 0.75 | I9: FAIL | J9: =COUNTIF('Test Results'!$F$5:$F$34,"FAIL") -> 0
A10: Inventory & Stores | B10: =COUNTIF('Gap Register'!$B$5:$B$126,A10) -> 39 | C10: =COUNTIFS('Gap Register'!$B$5:$B$126,$A10,'Gap Register'!$G$5:$G$126,"Met") -> 26 | D10: =COUNTIFS('Gap Register'!$B$5:$B$126,$A10,'Gap Register'!$G$5:$G$126,"Partially met") -> 13 | E10: =COUNTIFS('Gap Register'!$B$5:$B$126,$A10,'Gap Register'!$G$5:$G$126,"Not met") -> 0 | F10: =IFERROR(C10/B10,0) -> 0.66666667 | G10: =IFERROR((C10+Legend!$B$34*D10)/B10,0) -> 0.83333333 | I10: Total | J10: =SUM(J5:J9) -> 30
A11: Requisition & Workflow | B11: =COUNTIF('Gap Register'!$B$5:$B$126,A11) -> 14 | C11: =COUNTIFS('Gap Register'!$B$5:$B$126,$A11,'Gap Register'!$G$5:$G$126,"Met") -> 9 | D11: =COUNTIFS('Gap Register'!$B$5:$B$126,$A11,'Gap Register'!$G$5:$G$126,"Partially met") -> 5 | E11: =COUNTIFS('Gap Register'!$B$5:$B$126,$A11,'Gap Register'!$G$5:$G$126,"Not met") -> 0 | F11: =IFERROR(C11/B11,0) -> 0.64285714 | G11: =IFERROR((C11+Legend!$B$34*D11)/B11,0) -> 0.82142857
A12: Field Installation | B12: =COUNTIF('Gap Register'!$B$5:$B$126,A12) -> 14 | C12: =COUNTIFS('Gap Register'!$B$5:$B$126,$A12,'Gap Register'!$G$5:$G$126,"Met") -> 9 | D12: =COUNTIFS('Gap Register'!$B$5:$B$126,$A12,'Gap Register'!$G$5:$G$126,"Partially met") -> 5 | E12: =COUNTIFS('Gap Register'!$B$5:$B$126,$A12,'Gap Register'!$G$5:$G$126,"Not met") -> 0 | F12: =IFERROR(C12/B12,0) -> 0.64285714 | G12: =IFERROR((C12+Legend!$B$34*D12)/B12,0) -> 0.82142857 | I12: Defects (gap analysis) | J12: Count
A13: Exception Management | B13: =COUNTIF('Gap Register'!$B$5:$B$126,A13) -> 11 | C13: =COUNTIFS('Gap Register'!$B$5:$B$126,$A13,'Gap Register'!$G$5:$G$126,"Met") -> 6 | D13: =COUNTIFS('Gap Register'!$B$5:$B$126,$A13,'Gap Register'!$G$5:$G$126,"Partially met") -> 5 | E13: =COUNTIFS('Gap Register'!$B$5:$B$126,$A13,'Gap Register'!$G$5:$G$126,"Not met") -> 0 | F13: =IFERROR(C13/B13,0) -> 0.54545455 | G13: =IFERROR((C13+Legend!$B$34*D13)/B13,0) -> 0.77272727 | I13: Fixed | J13: =COUNTIF(Defects!$F$5:$F$10,"Fixed") -> 6
A14: Reporting & Dashboards | B14: =COUNTIF('Gap Register'!$B$5:$B$126,A14) -> 10 | C14: =COUNTIFS('Gap Register'!$B$5:$B$126,$A14,'Gap Register'!$G$5:$G$126,"Met") -> 4 | D14: =COUNTIFS('Gap Register'!$B$5:$B$126,$A14,'Gap Register'!$G$5:$G$126,"Partially met") -> 6 | E14: =COUNTIFS('Gap Register'!$B$5:$B$126,$A14,'Gap Register'!$G$5:$G$126,"Not met") -> 0 | F14: =IFERROR(C14/B14,0) -> 0.4 | G14: =IFERROR((C14+Legend!$B$34*D14)/B14,0) -> 0.7 | I14: Still open | J14: =COUNTIF(Defects!$F$5:$F$10,"Open") -> 0
A15: Notifications & Alerts | B15: =COUNTIF('Gap Register'!$B$5:$B$126,A15) -> 5 | C15: =COUNTIFS('Gap Register'!$B$5:$B$126,$A15,'Gap Register'!$G$5:$G$126,"Met") -> 5 | D15: =COUNTIFS('Gap Register'!$B$5:$B$126,$A15,'Gap Register'!$G$5:$G$126,"Partially met") -> 0 | E15: =COUNTIFS('Gap Register'!$B$5:$B$126,$A15,'Gap Register'!$G$5:$G$126,"Not met") -> 0 | F15: =IFERROR(C15/B15,0) -> 1 | G15: =IFERROR((C15+Legend!$B$34*D15)/B15,0) -> 1 | I15: Total | J15: =SUM(J13:J14) -> 6
A16: Security, Access & Audit | B16: =COUNTIF('Gap Register'!$B$5:$B$126,A16) -> 9 | C16: =COUNTIFS('Gap Register'!$B$5:$B$126,$A16,'Gap Register'!$G$5:$G$126,"Met") -> 3 | D16: =COUNTIFS('Gap Register'!$B$5:$B$126,$A16,'Gap Register'!$G$5:$G$126,"Partially met") -> 6 | E16: =COUNTIFS('Gap Register'!$B$5:$B$126,$A16,'Gap Register'!$G$5:$G$126,"Not met") -> 0 | F16: =IFERROR(C16/B16,0) -> 0.33333333 | G16: =IFERROR((C16+Legend!$B$34*D16)/B16,0) -> 0.66666667
A17: Total | B17: =SUM(B9:B16) -> 122 | C17: =SUM(C9:C16) -> 72 | D17: =SUM(D9:D16) -> 50 | E17: =SUM(E9:E16) -> 0 | F17: =IFERROR(C17/B17,0) -> 0.59016393 | G17: =IFERROR((C17+Legend!$B$34*D17)/B17,0) -> 0.79508197 | I17: Other coverage — met | J17: Met / total
I18: Business rules | J18: =COUNTIF('Rules & Reports'!$C$6:$C$38,"Met")&" / "&COUNTA('Rules & Reports'!$C$6:$C$38) -> 30 / 33
A19: Priority | B19: Requirements | C19: Met | D19: Partially met | E19: Not met | F19: % met | G19: Readiness | I19: Reports | J19: =COUNTIF('Rules & Reports'!$C$42:$C$61,"Met")&" / "&COUNTA('Rules & Reports'!$C$42:$C$61) -> 13 / 20
A20: M — Must have | B20: =COUNTIF('Gap Register'!$E$5:$E$126,"M") -> 101 | C20: =COUNTIFS('Gap Register'!$E$5:$E$126,"M",'Gap Register'!$G$5:$G$126,"Met") -> 55 | D20: =COUNTIFS('Gap Register'!$E$5:$E$126,"M",'Gap Register'!$G$5:$G$126,"Partially met") -> 46 | E20: =COUNTIFS('Gap Register'!$E$5:$E$126,"M",'Gap Register'!$G$5:$G$126,"Not met") -> 0 | F20: =IFERROR(C20/B20,0) -> 0.54455446 | G20: =IFERROR((C20+Legend!$B$34*D20)/B20,0) -> 0.77227723 | I20: Notifications | J20: =COUNTIF('Rules & Reports'!$C$65:$C$81,"Met")&" / "&COUNTA('Rules & Reports'!$C$65:$C$81) -> 17 / 17
A21: S — Should have | B21: =COUNTIF('Gap Register'!$E$5:$E$126,"S") -> 20 | C21: =COUNTIFS('Gap Register'!$E$5:$E$126,"S",'Gap Register'!$G$5:$G$126,"Met") -> 16 | D21: =COUNTIFS('Gap Register'!$E$5:$E$126,"S",'Gap Register'!$G$5:$G$126,"Partially met") -> 4 | E21: =COUNTIFS('Gap Register'!$E$5:$E$126,"S",'Gap Register'!$G$5:$G$126,"Not met") -> 0 | F21: =IFERROR(C21/B21,0) -> 0.8 | G21: =IFERROR((C21+Legend!$B$34*D21)/B21,0) -> 0.9
A22: C — Could have | B22: =COUNTIF('Gap Register'!$E$5:$E$126,"C") -> 1 | C22: =COUNTIFS('Gap Register'!$E$5:$E$126,"C",'Gap Register'!$G$5:$G$126,"Met") -> 1 | D22: =COUNTIFS('Gap Register'!$E$5:$E$126,"C",'Gap Register'!$G$5:$G$126,"Partially met") -> 0 | E22: =COUNTIFS('Gap Register'!$E$5:$E$126,"C",'Gap Register'!$G$5:$G$126,"Not met") -> 0 | F22: =IFERROR(C22/B22,0) -> 1 | G22: =IFERROR((C22+Legend!$B$34*D22)/B22,0) -> 1 | I22: Deployment check (LAN) | J22: Checks
I23: Met | J23: =COUNTIF('Deployment Check'!$E$5:$E$20,"Met") -> 7
I24: Fixed | J24: =COUNTIF('Deployment Check'!$E$5:$E$20,"Fixed") -> 2
A25: Remediation wave | B25: Work packages | C25: Est. person-days | D25: Open requirements addressed | I25: To verify | J25: =COUNTIF('Deployment Check'!$E$5:$E$20,"To verify") -> 1
A26: Wave 0 — Fix now | B26: =COUNTIF('Remediation Plan'!$B$5:$B$17,A26) -> 1 | C26: =SUMIF('Remediation Plan'!$B$5:$B$17,A26,'Remediation Plan'!$F$5:$F$17) -> 5 | D26: =SUMIF('Remediation Plan'!$B$5:$B$17,A26,'Remediation Plan'!$G$5:$G$17) -> 5 | I26: Risk | J26: =COUNTIF('Deployment Check'!$E$5:$E$20,"Risk") -> 1
A27: Wave 1 — Align | B27: =COUNTIF('Remediation Plan'!$B$5:$B$17,A27) -> 7 | C27: =SUMIF('Remediation Plan'!$B$5:$B$17,A27,'Remediation Plan'!$F$5:$F$17) -> 50 | D27: =SUMIF('Remediation Plan'!$B$5:$B$17,A27,'Remediation Plan'!$G$5:$G$17) -> 31 | I27: Not tested | J27: =COUNTIF('Deployment Check'!$E$5:$E$20,"Not tested") -> 1
A28: Wave 2 — Field app | B28: =COUNTIF('Remediation Plan'!$B$5:$B$17,A28) -> 2 | C28: =SUMIF('Remediation Plan'!$B$5:$B$17,A28,'Remediation Plan'!$F$5:$F$17) -> 25 | D28: =SUMIF('Remediation Plan'!$B$5:$B$17,A28,'Remediation Plan'!$G$5:$G$17) -> 5 | I28: Not met | J28: =COUNTIF('Deployment Check'!$E$5:$E$20,"Not met") -> 4
A29: Wave 3 — Stock control | B29: =COUNTIF('Remediation Plan'!$B$5:$B$17,A29) -> 1 | C29: =SUMIF('Remediation Plan'!$B$5:$B$17,A29,'Remediation Plan'!$F$5:$F$17) -> 20 | D29: =SUMIF('Remediation Plan'!$B$5:$B$17,A29,'Remediation Plan'!$G$5:$G$17) -> 2 | I29: Blocked | J29: =COUNTIF('Deployment Check'!$E$5:$E$20,"Blocked") -> 0
A30: Wave 4 — Notify & report | B30: =COUNTIF('Remediation Plan'!$B$5:$B$17,A30) -> 2 | C30: =SUMIF('Remediation Plan'!$B$5:$B$17,A30,'Remediation Plan'!$F$5:$F$17) -> 20 | D30: =SUMIF('Remediation Plan'!$B$5:$B$17,A30,'Remediation Plan'!$G$5:$G$17) -> 7 | I30: Total | J30: =SUM(J23:J29) -> 16
A31: Total | B31: =SUM(B26:B30) -> 13 | C31: =SUM(C26:C30) -> 120 | D31: =SUM(D26:D30) -> 50
A32: Person-days are planning estimates from the size table on the Legend sheet — adjust there.
A34: Key findings
A35: 1. Remediation of 18-09-2026: every requirement that was Not met is now Met — the SLIMS Field Android app (live capture, mock-location detection, offline queue, device binding), evidence integrity, the quantity ledger with transfers, adjustments, physical verification and reconciliation, the approval matrix, notifications with escalation, drill-down, map and scheduled reports.
A36: 2. All six defects are fixed and their probes pass in the acceptance run, including the two High ones (DF-01 audit scope, DF-06 cancel scope).
A37: 3. What remains is Partially met: mostly vocabulary and structure the FRD settled in reconciliation (roles, Store → Rack → Shelf → Bin naming, evidence status values), the over-receipt exception route (TC-05), refused attempts in the audit trail (TC-27) and before-values on every stock movement (TC-30).
A38: 4. The core control chain works end to end: QR receipt against PO into Receiving, put-away, site-bound requisition with delegated approval, scan-based issue, geo-fence validation from the bound phone, quarantine returns with a Usable route, warranty and approved disposal.
A39: 5. E-mail and SMS copies need only the department's own mail server and SMS gateway entered under Parameters; nothing paid is built in.
A40: 6. The LAN deployment behaves exactly like development and is fast, but it is not ready for field roll-out. It serves plain HTTP, so phone browsers refuse GPS to the evidence screen. It also has no backup, no trusted time source and no auto-restart. See the Deployment Check sheet.

Sheet Gap Register
A1: Gap register — every FRD-GSL-001 requirement against the current build
A2: Filter by module, status, priority or work package. Edit Status as work lands; Wave is looked up from the Remediation Plan.
A4: FR ID | B4: Module | C4: Area | D4: Requirement (FRD-GSL-001) | E4: Pri. | F4: Process stage | G4: Status | H4: Current build (evidence) | I4: Gap | J4: Remediation | K4: Work package | L4: Wave | M4: Acceptance tests | N4: Test results | O4: Source trace
A5: FR-MDM-001 | B5: Master Data | C5: Item / article master | D5: The system shall create articles article-wise, one per purchase order line, with a unique Item Code composed as CATEGORY-SUBCATEGORY-SPECIFICATION-PO-LINE (for example `LUM-LED-090W-PO2611-001`). The PO number and line are part of the code and remain attached to the item for life. | E5: M | F5: 1 Procurement / PO | G5: Met | H5: MasterService.CreateArticleAsync builds CAT-SUB-SPEC-PO-LINE through Codes.ItemCode; an article needs an open PO line. | I5: — | J5: — | L5: =IF(K5="","",INDEX('Remediation Plan'!$B$5:$B$17,MATCH(K5,'Remediation Plan'!$A$5:$A$17,0))) | M5: — | N5: — | O5: G: §5.1 · S: FR-MD-05, BR-003, BR-004
A6: FR-MDM-002 | B6: Master Data | C6: Item / article master | D6: The article master shall hold description, category, sub-category, specification / model, unit of measure, serialised or bulk tracking, pack size, rate, warranty period, expected service life, re-order level, status (Active, Blocked, Obsolete) and PO reference history. | E6: M | F6: 1 Procurement / PO | G6: Met | H6: Article entity holds every listed field; PO reference kept through the PO line. | I6: — | J6: — | L6: =IF(K6="","",INDEX('Remediation Plan'!$B$5:$B$17,MATCH(K6,'Remediation Plan'!$A$5:$A$17,0))) | M6: — | N6: — | O6: G: §5.1 · S: §9.3
A7: FR-MDM-003 | B7: Master Data | C7: Item / article master | D7: The unit of measure of an article shall be locked once any transaction exists against it. | E7: M | F7: 1 Procurement / PO | G7: Met | H7: Article UoM cannot be changed after creation (UpdateArticleAsync edits only re-order level, status, life). | I7: The PO line's UoM can still be changed through the API — see DF-04. | J7: Covered by the DF-04 fix. | K7: WP-00 | L7: =IF(K7="","",INDEX('Remediation Plan'!$B$5:$B$17,MATCH(K7,'Remediation Plan'!$A$5:$A$17,0))) -> Wave 0 — Fix now | M7: — | N7: — | O7: S: FR-MD-08, BR-028
A8: FR-MDM-004 | B8: Master Data | C8: Item / article master | D8: A Blocked or Obsolete article shall not be selectable on a requisition or issuable; its existing stock remains visible in all enquiries. | E8: M | F8: 1 Procurement / PO | G8: Partially met | H8: Requisition creation refuses a Blocked or Obsolete article (RequisitionService.CreateAsync). | I8: Issue does not re-check article status, so an article blocked after approval can still be issued. | J8: Re-check article status at issue scan and posting. | K8: WP-00 | L8: =IF(K8="","",INDEX('Remediation Plan'!$B$5:$B$17,MATCH(K8,'Remediation Plan'!$A$5:$A$17,0))) -> Wave 0 — Fix now | M8: — | N8: — | O8: G: §5.1
A9: FR-MDM-005 | B9: Master Data | C9: QR identification | D9: On article creation the system shall generate one unique QR identifier per serialised unit, or per pack / batch for bulk articles. The payload shall carry the item code, a serial number and a check value derived from both (format in Section 8.5). | E9: M | F9: 1 Procurement / PO | G9: Met | H9: One label per piece or pack with SHA-256-derived check value (Codes.QrPayload). | I9: — | J9: — | L9: =IF(K9="","",INDEX('Remediation Plan'!$B$5:$B$17,MATCH(K9,'Remediation Plan'!$A$5:$A$17,0))) | M9: — | N9: — | O9: G: §5.5 · S: FR-MD-06
A10: FR-MDM-006 | B10: Master Data | C10: QR identification | D10: A QR identifier shall be unique across the whole system and never reused, including after the item is disposed. A scan shall never create a duplicate item record. | E10: M | F10: 1 Procurement / PO | G10: Met | H10: Unique indexes on QR payload and (article, serial); forged and repeated labels refused (TC-03, TC-04). | I10: — | J10: — | L10: =IF(K10="","",INDEX('Remediation Plan'!$B$5:$B$17,MATCH(K10,'Remediation Plan'!$A$5:$A$17,0))) | M10: TC-03, TC-04 | N10: TC-03 PASS; TC-04 PASS | O10: G: §10, Rule 2 · S: BR-002
A11: FR-MDM-007 | B11: Master Data | C11: QR identification | D11: Scanning a QR in any function shall retrieve the item record with its current status, current store location or site, PO reference and full transaction history. | E11: M | F11: 4 Store Inventory | G11: Met | H11: GET /api/items/{id or QR} returns status, location or site, PO and history; every scan response carries the item state. | I11: — | J11: — | L11: =IF(K11="","",INDEX('Remediation Plan'!$B$5:$B$17,MATCH(K11,'Remediation Plan'!$A$5:$A$17,0))) | M11: — | N11: — | O11: G: §5.5, FR-14 · S: FR-IC-09
A12: FR-MDM-008 | B12: Master Data | C12: QR identification | D12: The system shall print label sheets showing the QR symbol, item code, description, PO number and serial. A re-print shall carry the same identifier and be logged against the item with the reason. | E12: M | F12: 1 Procurement / PO | G12: Partially met | H12: Label sheet generated; every re-print is logged as “print #n” (MasterService.LabelsAsync). | I12: No reason is captured for a re-print. | J12: Ask for and store a reason when a label is re-printed. | K12: WP-03 | L12: =IF(K12="","",INDEX('Remediation Plan'!$B$5:$B$17,MATCH(K12,'Remediation Plan'!$A$5:$A$17,0))) -> Wave 1 — Align | M12: — | N12: — | O12: S: FR-MD-07, FR-MD-14
A13: FR-MDM-009 | B13: Master Data | C13: Purchase order reference | D13: The system shall hold approved purchase order references — PO number, vendor, PO date, delivery due date, warranty terms and lines (item description, category, specification, unit, quantity, rate) — entered by Procurement / Admin or received by interface. | E13: M | F13: 1 Procurement / PO | G13: Met | H13: POs, vendors and lines entered on the Purchase Orders screen (MasterService.UpsertPoAsync). | I13: Inbound PO interface (INT-01) not built — entry is manual. PO lines with articles are not locked at the API (DF-04). | J13: Build INT-01 when the procurement system is available. | K13: WP-00 | L13: =IF(K13="","",INDEX('Remediation Plan'!$B$5:$B$17,MATCH(K13,'Remediation Plan'!$A$5:$A$17,0))) -> Wave 0 — Fix now | M13: — | N13: — | O13: G: §5.2, FR-01 · S: INT-01
A14: FR-MDM-010 | B14: Master Data | C14: Purchase order reference | D14: For every PO line the system shall maintain ordered, received and outstanding quantities, updated on each receipt and each reversal. | E14: M | F14: 1 Procurement / PO | G14: Met | H14: Ordered, received and outstanding shown per PO line, recomputed from item status. | I14: — | J14: — | L14: =IF(K14="","",INDEX('Remediation Plan'!$B$5:$B$17,MATCH(K14,'Remediation Plan'!$A$5:$A$17,0))) | M14: — | N14: — | O14: G: §5.2
A15: FR-MDM-011 | B15: Master Data | C15: Purchase order reference | D15: Procurement / Admin shall be able to close and re-open a PO. A closed PO accepts no further receipts. | E15: S | F15: 1 Procurement / PO | G15: Met | H15: PO open / close toggle; closed PO refuses receipts. | I15: — | J15: — | L15: =IF(K15="","",INDEX('Remediation Plan'!$B$5:$B$17,MATCH(K15,'Remediation Plan'!$A$5:$A$17,0))) | M15: — | N15: — | O15: —
A16: FR-MDM-012 | B16: Master Data | C16: Store location master | D16: The system shall maintain store locations in the hierarchy Store / Warehouse → Rack → Shelf → Bin and generate a unique location code for each bin (for example `CEN01-R04-S02-B12`). Stock balance shall be held at bin level. | E16: M | F16: 3 QR Scan & Put-away | G16: Partially met | H16: Locations are Store ▸ Section ▸ Rack ▸ Bin (StoreLocation entity). | I16: No Shelf level; hierarchy differs from Store → Rack → Shelf → Bin. | J16: Restructure to Rack / Shelf / Bin and regenerate location codes. | K16: WP-02 | L16: =IF(K16="","",INDEX('Remediation Plan'!$B$5:$B$17,MATCH(K16,'Remediation Plan'!$A$5:$A$17,0))) -> Wave 1 — Align | M16: — | N16: — | O16: G: §5.3, FR-03 · S: §9.1
A17: FR-MDM-013 | B17: Master Data | C17: Store location master | D17: Each location shall be typed Receiving, Stock, Quarantine, Repair or Scrap. Only Stock locations hold issuable material. Every store shall have at least one location of each type. | E17: M | F17: 3 QR Scan & Put-away | G17: Partially met | H17: Location kinds Stock, Quarantine and Scrap; new stores get a Quarantine and a Scrap bin automatically. | I17: No Receiving or Repair location types. | J17: Add Receiving and Repair kinds. | K17: WP-02 | L17: =IF(K17="","",INDEX('Remediation Plan'!$B$5:$B$17,MATCH(K17,'Remediation Plan'!$A$5:$A$17,0))) -> Wave 1 — Align | M17: — | N17: — | O17: G: §7 · S: BR-018
A18: FR-MDM-014 | B18: Master Data | C18: Store location master | D18: A store or location holding stock shall not be deactivated. | E18: M | F18: 3 QR Scan & Put-away | G18: Met | H18: Deactivating a store or bin holding stock is refused (BR-024 check in MasterService). | I18: — | J18: — | L18: =IF(K18="","",INDEX('Remediation Plan'!$B$5:$B$17,MATCH(K18,'Remediation Plan'!$A$5:$A$17,0))) | M18: — | N18: — | O18: S: BR-024
A19: FR-MDM-015 | B19: Master Data | C19: Site master | D19: The system shall maintain one record per lighting site with a unique Site ID, name / description, administrative hierarchy (Zone → Division → Ward / UC), site type, latitude and longitude to six decimal places, geofence radius, tolerance, assigned Lighting Supervisor and Lighting Officer, and status (Planned, Active, Completed, On hold). | E19: M | F19: 5 Digital Requisition | G19: Partially met | H19: Site record holds ID, name, zone, division, ward, type, coordinates, geofence, supervisor, officer, status. | I19: Tolerance is a single global parameter; no per-site tolerance. | J19: Add an optional per-site tolerance. | K19: WP-12 | L19: =IF(K19="","",INDEX('Remediation Plan'!$B$5:$B$17,MATCH(K19,'Remediation Plan'!$A$5:$A$17,0))) -> Wave 1 — Align | M19: — | N19: — | O19: G: §5.4, Rule 10 · S: §9.2
A20: FR-MDM-016 | B20: Master Data | C20: Site master | D20: Sites shall be loadable in bulk from a survey file, with every row validated and rejected rows reported with the reason. | E20: S | F20: 5 Digital Requisition | G20: Partially met | H20: POST /api/sites/bulk takes a JSON array and reports errors by row. | I20: No CSV / Excel survey-file upload in the portal. | J20: Accept CSV and Excel files and map columns. | K20: WP-12 | L20: =IF(K20="","",INDEX('Remediation Plan'!$B$5:$B$17,MATCH(K20,'Remediation Plan'!$A$5:$A$17,0))) -> Wave 1 — Align | M20: — | N20: — | O20: S: FR-MD-04
A21: FR-MDM-017 | B21: Master Data | C21: Site master | D21: Changing the coordinates or geofence of a site that has had material issued to it shall require authorised approval, and the previous values shall be retained in the site history. | E21: M | F21: 5 Digital Requisition | G21: Partially met | H21: Changing coordinates of a site with issued material needs a configuring role; previous values kept in the audit trail. | I21: No approval step and no site-history view. | J21: Route the change for approval and show site history. | K21: WP-12 | L21: =IF(K21="","",INDEX('Remediation Plan'!$B$5:$B$17,MATCH(K21,'Remediation Plan'!$A$5:$A$17,0))) -> Wave 1 — Align | M21: — | N21: — | O21: G: §9 · S: BR-025
A22: FR-MDM-018 | B22: Master Data | C22: Scope, reason codes and parameters | D22: The system shall maintain the organisational hierarchy used for data scope (Zone, Division, Ward / UC) and the assignment of users to stores and sites. | E22: M | F22: 11 Reporting | G22: Partially met | H22: Scope is zone plus optional stores and sites per user. | I22: No Division or Ward / UC level of scope. | J22: Add division and ward levels to the scope model. | K22: WP-12 | L22: =IF(K22="","",INDEX('Remediation Plan'!$B$5:$B$17,MATCH(K22,'Remediation Plan'!$A$5:$A$17,0))) -> Wave 1 — Align | M22: — | N22: — | O22: G: §4
A23: FR-MDM-019 | B23: Master Data | C23: Scope, reason codes and parameters | D23: The system shall maintain reason-code lists for requisition rejection, receipt discrepancy, failure and condition, stock adjustment and exception resolution. | E23: M | F23: 11 Reporting | G23: Partially met | H23: Failure reasons are a configurable list. | I23: Rejection, discrepancy, adjustment and resolution reasons are free text. | J23: Add maintained reason-code lists and use them on those screens. | K23: WP-01 | L23: =IF(K23="","",INDEX('Remediation Plan'!$B$5:$B$17,MATCH(K23,'Remediation Plan'!$A$5:$A$17,0))) -> Wave 1 — Align | M23: — | N23: — | O23: S: §9.5
A24: FR-MDM-020 | B24: Master Data | C24: Scope, reason codes and parameters | D24: Authorised administrators shall configure, without code changes: default geofence radius, tolerance, minimum GPS accuracy, permitted clock drift, return period, reservation validity, acknowledgement period, ageing threshold, evidence size limit and minimum justification length. | E24: M | F24: 11 Reporting | G24: Partially met | H24: Ten parameters editable on the Parameters screen. | I24: Minimum justification length is hard-coded (10); reservation validity is stored but has no effect. | J24: Make the justification length a parameter; implement the reservation lapse. | K24: WP-12 | L24: =IF(K24="","",INDEX('Remediation Plan'!$B$5:$B$17,MATCH(K24,'Remediation Plan'!$A$5:$A$17,0))) -> Wave 1 — Align | M24: — | N24: — | O24: G: §14 · S: FR-MD-12
A25: FR-INV-001 | B25: Inventory & Stores | C25: Goods receipt | D25: The Store / Warehouse Officer shall start a receipt by selecting an open PO. The system shall display each PO line with ordered, received and outstanding quantity. | E25: M | F25: 2 Goods Receipt | G25: Met | H25: Goods Receipt screen lists open POs with ordered, received and outstanding (TC-01). | I25: — | J25: — | L25: =IF(K25="","",INDEX('Remediation Plan'!$B$5:$B$17,MATCH(K25,'Remediation Plan'!$A$5:$A$17,0))) | M25: — | N25: — | O25: G: FR-01, Rule 1 · S: FR-GR-01
A26: FR-INV-002 | B26: Inventory & Stores | C26: Goods receipt | D26: Each serialised or controlled item shall be received by scanning its QR. On every scan the system shall validate that the label is genuine, belongs to the selected PO, has not already been received, and that the receipt will not exceed the PO line balance — and show the result immediately. | E26: M | F26: 2 Goods Receipt | G26: Met | H26: Every scan validated for label, PO, prior receipt and balance (GrnService.ValidateAsync; TC-01, 03, 04). | I26: — | J26: — | L26: =IF(K26="","",INDEX('Remediation Plan'!$B$5:$B$17,MATCH(K26,'Remediation Plan'!$A$5:$A$17,0))) | M26: TC-01, TC-03 | N26: TC-01 PASS; TC-03 PASS | O26: G: FR-01, FR-02, Rule 2 · S: FR-GR-02, FR-GR-03
A27: FR-INV-003 | B27: Inventory & Stores | C27: Goods receipt | D27: Receipt without a PO reference shall not be possible through the standard receipt function. | E27: M | F27: 2 Goods Receipt | G27: Met | H27: A receipt cannot be posted without a PO (TC-02). | I27: Refused as “PO not found” rather than a prompt to select a PO. | J27: Align the message with VAL-INV-001. | K27: WP-03 | L27: =IF(K27="","",INDEX('Remediation Plan'!$B$5:$B$17,MATCH(K27,'Remediation Plan'!$A$5:$A$17,0))) -> Wave 1 — Align | M27: TC-02 | N27: TC-02 PASS* | O27: G: Rule 1
A28: FR-INV-004 | B28: Inventory & Stores | C28: Goods receipt | D28: Receipt beyond the PO line balance shall be blocked unless an over-receipt exception is recorded with a reason and approved by an authorised officer; the exception is linked to the GRN. | E28: M | F28: 2 Goods Receipt | G28: Partially met | H28: Receipt beyond PO balance is blocked (TC-05). | I28: No over-receipt exception request or approval. | J28: Add over-receipt exception with reason and Approving Officer approval. | K28: WP-03 | L28: =IF(K28="","",INDEX('Remediation Plan'!$B$5:$B$17,MATCH(K28,'Remediation Plan'!$A$5:$A$17,0))) -> Wave 1 — Align | M28: TC-05 | N28: TC-05 PARTIAL | O28: G: §5.2, Rule 9 · S: BR-014
A29: FR-INV-005 | B29: Inventory & Stores | C29: Goods receipt | D29: The receiver shall record the physical condition of the consignment and may reject individual items with a reason code and optional photograph. Rejected items do not enter stock. | E29: M | F29: 2 Goods Receipt | G29: Met | H29: GrnService.PostAsync records the consignment condition and per-label rejection with reason code and optional photograph; rejected labels never enter stock and raise a Rejected discrepancy note (FR-INV-005 check). Implemented 18-09-2026. | I29: — | J29: — | K29: WP-03 | L29: =IF(K29="","",INDEX('Remediation Plan'!$B$5:$B$17,MATCH(K29,'Remediation Plan'!$A$5:$A$17,0))) -> Wave 1 — Align | M29: — | N29: — | O29: G: §7, §8 · S: FR-GR-05
A30: FR-INV-006 | B30: Inventory & Stores | C30: Goods receipt | D30: The system shall generate a discrepancy / short-receipt note for any shortage, excess or rejection and route it to Procurement / Admin, who record its resolution. | E30: M | F30: 2 Goods Receipt | G30: Partially met | H30: Discrepancy notes raised by hand and resolved by Procurement (GrnService.RaiseDiscrepancyAsync). | I30: Notes are not generated automatically from a short or rejected receipt. | J30: Generate the note from the receipt. | K30: WP-03 | L30: =IF(K30="","",INDEX('Remediation Plan'!$B$5:$B$17,MATCH(K30,'Remediation Plan'!$A$5:$A$17,0))) -> Wave 1 — Align | M30: — | N30: — | O30: G: FR-12 · S: FR-GR-06
A31: FR-INV-007 | B31: Inventory & Stores | C31: Goods receipt | D31: The receipt shall capture delivery challan number, invoice number and date, receipt date and receiver, and generate a sequential, non-editable GRN number. | E31: M | F31: 2 Goods Receipt | G31: Met | H31: GRN number, challan, invoice number and date, receiver and time recorded. | I31: — | J31: — | L31: =IF(K31="","",INDEX('Remediation Plan'!$B$5:$B$17,MATCH(K31,'Remediation Plan'!$A$5:$A$17,0))) | M31: TC-01 | N31: TC-01 PASS | O31: G: §8 · S: FR-GR-09, FR-GR-10
A32: FR-INV-008 | B32: Inventory & Stores | C32: Goods receipt | D32: Partial receipt against a PO line shall be supported; the balance remains open for later receipts. | E32: M | F32: 2 Goods Receipt | G32: Met | H32: Partial receipt leaves the PO line open. | I32: — | J32: — | L32: =IF(K32="","",INDEX('Remediation Plan'!$B$5:$B$17,MATCH(K32,'Remediation Plan'!$A$5:$A$17,0))) | M32: — | N32: — | O32: S: FR-GR-11
A33: FR-INV-009 | B33: Inventory & Stores | C33: Goods receipt | D33: An authorised user may reverse a GRN, with a reason, provided none of its items has moved on. Both the original and the reversal remain visible. | E33: S | F33: 2 Goods Receipt | G33: Met | H33: GRN reversal with reason while no item has moved on (GrnService.ReverseAsync). | I33: — | J33: — | L33: =IF(K33="","",INDEX('Remediation Plan'!$B$5:$B$17,MATCH(K33,'Remediation Plan'!$A$5:$A$17,0))) | M33: — | N33: — | O33: S: FR-GR-13, BR-022
A34: FR-INV-010 | B34: Inventory & Stores | C34: Put-away and location | D34: Received items shall first be held in the store's Receiving location and shall not be available for requisition or issue. | E34: M | F34: 3 QR Scan & Put-away | G34: Met | H34: Receipts land in the store's Receiving location (StoreControlService.ReceivingLocationAsync); availability and issue accept only Stock bins (TC-06). Implemented 18-09-2026. | I34: — | J34: — | K34: WP-02 | L34: =IF(K34="","",INDEX('Remediation Plan'!$B$5:$B$17,MATCH(K34,'Remediation Plan'!$A$5:$A$17,0))) -> Wave 1 — Align | M34: TC-06 | N34: TC-06 PASS | O34: G: §7
A35: FR-INV-011 | B35: Inventory & Stores | C35: Put-away and location | D35: Put-away shall be recorded by scanning the item and the destination bin (Store → Rack → Shelf → Bin). The item becomes available only after successful put-away. Where the officer bins on receipt, receipt and put-away may be recorded in one step. | E35: M | F35: 3 QR Scan & Put-away | G35: Partially met | H35: The bin is chosen on the receipt and must be an active Stock bin. | I35: No scan-to-bin put-away step. | J35: Add put-away by scanning bin then items. | K35: WP-02 | L35: =IF(K35="","",INDEX('Remediation Plan'!$B$5:$B$17,MATCH(K35,'Remediation Plan'!$A$5:$A$17,0))) -> Wave 1 — Align | M35: TC-01 | N35: TC-01 PASS | O35: G: FR-03, §7 · S: FR-GR-07, BR-005
A36: FR-INV-012 | B36: Inventory & Stores | C36: Put-away and location | D36: Internal moves between bins shall be recorded by scanning the item and the new bin; the ledger records both locations. | E36: S | F36: 3 QR Scan & Put-away | G36: Met | H36: StoreControlService.MoveAsync: scan items and the bin label (SLIMSLOC|…); the ledger records both locations; put-away screen in the portal. Implemented 18-09-2026. | I36: — | J36: — | K36: WP-02 | L36: =IF(K36="","",INDEX('Remediation Plan'!$B$5:$B$17,MATCH(K36,'Remediation Plan'!$A$5:$A$17,0))) -> Wave 1 — Align | M36: — | N36: — | O36: G: §10
A37: FR-INV-013 | B37: Inventory & Stores | C37: Stock ledger and balances | D37: Every stock movement — receipt, put-away, bin move, transfer, issue, return, re-inward, adjustment and disposal — shall post a ledger entry with item, quantity, from and to location or site, transaction ID, user and timestamp. | E37: M | F37: 4 Store Inventory | G37: Partially met | H37: Each movement is written per item to the audit trail with from / to details. | I37: No quantity ledger with transaction IDs. | J37: Introduce a stock ledger table posted by every movement. | K37: WP-09 | L37: =IF(K37="","",INDEX('Remediation Plan'!$B$5:$B$17,MATCH(K37,'Remediation Plan'!$A$5:$A$17,0))) -> Wave 3 — Stock control | M37: TC-15 | N37: TC-15 PASS | O37: G: Rule 8, §10 · S: FR-IC-01
A38: FR-INV-014 | B38: Inventory & Stores | C38: Stock ledger and balances | D38: Each controlled item shall have exactly one current inventory state and one current location or site at any time. | E38: M | F38: 4 Store Inventory | G38: Partially met | H38: Each item carries one status and a location or site. | I38: A returned item keeps its site while in quarantine (DF-03). | J38: Clear the site when a return is received. | K38: WP-00 | L38: =IF(K38="","",INDEX('Remediation Plan'!$B$5:$B$17,MATCH(K38,'Remediation Plan'!$A$5:$A$17,0))) -> Wave 0 — Fix now | M38: — | N38: — | O38: G: §10, FR-14
A39: FR-INV-015 | B39: Inventory & Stores | C39: Stock ledger and balances | D39: The system shall show, for each item code and location: on hand, reserved, available, in quarantine and in transit. | E39: M | F39: 4 Store Inventory | G39: Partially met | H39: Stock screen shows on hand, reserved and available by bin; quarantine and scrap bins shown separately. | I39: No in-transit figure (transfers not built). | J39: Add in-transit with transfers. | K39: WP-09 | L39: =IF(K39="","",INDEX('Remediation Plan'!$B$5:$B$17,MATCH(K39,'Remediation Plan'!$A$5:$A$17,0))) -> Wave 3 — Stock control | M39: — | N39: — | O39: G: §11 · S: FR-IC-02
A40: FR-INV-016 | B40: Inventory & Stores | C40: Stock ledger and balances | D40: The system shall reconcile stock for any store and period as Opening + Receipts + Returns − Issues − Approved Adjustments = Closing (Section 13.2), and report any line that does not balance. | E40: M | F40: 4 Store Inventory | G40: Met | H40: StockMovement ledger written by every quantity change; report “Stock Reconciliation (RPT-04)” balances every store × article line (TC-29). Implemented 18-09-2026. | I40: — | J40: — | K40: WP-09 | L40: =IF(K40="","",INDEX('Remediation Plan'!$B$5:$B$17,MATCH(K40,'Remediation Plan'!$A$5:$A$17,0))) -> Wave 3 — Stock control | M40: TC-29 | N40: TC-29 PASS | O40: G: §10
A41: FR-INV-017 | B41: Inventory & Stores | C41: Stock ledger and balances | D41: No transaction shall reduce stock at any location below zero. | E41: M | F41: 4 Store Inventory | G41: Met | H41: Stock is the sum of labels and a label cannot move twice, so negative stock cannot arise. | I41: — | J41: — | L41: =IF(K41="","",INDEX('Remediation Plan'!$B$5:$B$17,MATCH(K41,'Remediation Plan'!$A$5:$A$17,0))) | M41: — | N41: — | O41: S: BR-021
...

Sheet Test Results
A1: Acceptance tests — FRD Section 21 run against the live build
A2: Run 2026-09-18 14:12:13 · API http://172.16.10.184:3001 · tag 09181411
A4: TC | B4: Scenario | C4: Steps (FRD) | D4: Expected (FRD) | E4: Observed in the live run | F4: Result | G4: Note | H4: Requirements | I4: Rules
A5: TC-01 | B5: Receive a PO-referenced article by QR into a bin | C5: Select store and PO; scan 5 labels; choose a Stock bin; post | D5: GRN numbered; items In Store at the bin; PO outstanding reduced by 5; ledger shows 5 receipts | E5: GRN GRN/CEN01/26-27/00006; 5 Received into CEN01-RCV-R0-B0, then put away by scan to CEN01-QA-R1411-B1; PO line received 5.0 of 10.0 | F5: PASS | G5: — | H5: FR-INV-002, FR-INV-007, FR-INV-011 | I5: BR-01, BR-08
A6: TC-02 | B6: Receive without a PO | C6: Open receipt and scan without selecting a PO | D6: Refused — VAL-INV-001 | E6: Posting with no PO: HTTP 404 · None · Purchase order not found | F6: PASS* | G6: Refused, but as “Purchase order not found” rather than a prompt to select a PO | H6: FR-INV-003 | I6: BR-01
A7: TC-03 | B7: Scan a forged label | C7: Scan a payload with a wrong check value | D7: Refused — VAL-INV-003; attempt audited | E7: ok=False · step=BR-002 · Not a SLIMS label — the QR payload or its check value is invalid. | F7: PASS | G7: — | H7: FR-INV-002, FR-MDM-006 | I7: BR-02
A8: TC-04 | B8: Receive the same label twice | C8: Receive a label, then scan it on a new receipt | D8: Refused — VAL-INV-006 | E8: ok=False · Already Received — a label can only be received once. | F8: PASS | G8: — | H8: FR-MDM-006 | I8: BR-11
A9: TC-05 | B9: Receive beyond PO balance | C9: Scan one more label than outstanding; then request and approve an over-receipt exception | D9: First refused — VAL-INV-007; after approval the item is received and the exception is linked to the GRN | E9: Scan beyond balance: Receipt would exceed the PO line quantity (5.000+1.000 > 5.000).. No over-receipt exception function exists. | F9: PARTIAL | G9: The block holds; the approved-exception route is not built (outside the Not-met scope) | H9: FR-INV-004 | I9: BR-13, BR-09
A10: TC-06 | B10: Stock not yet put away is not available | C10: Receive to Receiving; open a requisition for the article | D10: Receiving quantity is not shown as available | E10: Available for requisition: 5.0 (8 received: 5 put away, 3 still in Receiving CEN01-RCV-R0-B0). Approval: reserved | F10: PASS | G10: — | H10: FR-INV-010 | I10: BR-14
A11: TC-07 | B11: Requisition for an unregistered or out-of-scope site | C11: Try to type a site name; try to select another supervisor's site | D11: No free-text field; out-of-scope site not selectable — VAL-REQ-002 | E11: Site ID is an integer reference (no free text). Another supervisor's site: HTTP 409 · BR-008 · Site SITE-C-MALL-0001 is assigned to another supervisor.. Other zone: HTTP 403 · scope · Site SITE-CLAHO-0004 is outside your scope. | F11: PASS | G11: — | H11: FR-REQ-002 | I11: BR-04, BR-18
A12: TC-08 | B12: Submit a requisition with a shortfall | C12: Request more than available; submit | D12: Warning VAL-REQ-004; requisition Submitted; indent recorded; Approving Officer notified | E12: Status Submitted; shortfall 4911.0; indent recorded True; required level 2; NTF-01 delivered to 1 approver(s) | F12: PASS | G12: — | H12: FR-REQ-005, FR-REQ-006, FR-NTF-001 | I12: —
A13: TC-09 | B13: Approve own requisition | C13: As a user with both rights, raise and approve | D13: Refused — VAL-REQ-005 | E13: HTTP 409 · BR-026 · You cannot approve a requisition you raised yourself. | F13: PASS | G13: — | H13: FR-REQ-011 | I13: BR-27
A14: TC-10 | B14: Approve in part | C14: Approve 3 of 5 requested | D14: 3 reserved; Issue Slip numbered; supervisor notified | E14: Status Approved; approved 3.0; 3 labels reserved; Issue Slip ISL/CEN01/26-27/00010; supervisor notified: yes (NTF-02) | F14: PASS | G14: — | H14: FR-REQ-009, FR-REQ-012 | I14: BR-15
A15: TC-11 | B15: Reject a requisition | C15: Reject without reason; then with reason | D15: First refused — VAL-REQ-006; then returned to supervisor with the reason | E15: Without reason: HTTP 400 · None · A reason is required to reject.. With reason: status Rejected; supervisor notified (NTF-03) | F15: PASS | G15: — | H15: FR-REQ-009, FR-REQ-013 | I15: —
... A34: TC-30 | B34: Audit completeness | C34: Perform one action of each type; open the audit trail | D34: Every action shows user, role, time, address and before / after values | E34: 499 QA actions audited; 499 with user, role and address; before-values present on 14 of 160 changes | F34: PARTIAL | G34: Before-values are recorded for moves, adjustments, amendments and master data; not yet for every stock movement | H34: FR-SEC-005, FR-SEC-006 | I34: BR-26
A36: Remediation checks — one per requirement closed on 18-09-2026, and the defect probes
A37: Check | B37: Requirement / defect | C37: Expected | D37: Observed in the live run | E37: Result
A38: DF-01 | B38: Defect fixed: audit trail scope | C38: Probe no longer reproduces the defect | D38: officer sees 64 rows, all their own | E38: PASS
A39: DF-02 | B39: Defect fixed: clock-drift limit | C39: Probe no longer reproduces the defect | D39: phone 30 min off: HTTP 409 · FR-FLD-011 · The phone clock is 30 minutes off server time (limit 5). Switch on automatic date and time. | E39: PASS
A40: DF-03 | B40: Defect fixed: returned item keeps its site | C40: Probe no longer reproduces the defect | D40: returned item carries no site in the store | E40: PASS
A41: DF-04 | B41: Defect fixed: PO line lock after article | C41: Probe no longer reproduces the defect | D41: re-specifying the line: HTTP 409 · FR-MD-05 · Line 1 already has article LUM-LED-090W-POQA09181411-001; its category, specification, description and unit can no longer change. Only quantity and rate can. | E41: PASS
A42: DF-05 | B42: Defect fixed: issue to On-hold site | C42: Probe no longer reproduces the defect | D42: issue to On-hold site: HTTP 409 · BR-007 · Site SITE-CLAHO-0004 is On hold; material cannot be issued to it. | E42: PASS
A43: DF-06 | B43: Defect fixed: cancel ignores scope | C43: Probe no longer reproduces the defect | D43: out-of-scope cancel: HTTP 403 · scope · Site SITE-N-GTRD-0004 is outside your scope. | E43: PASS
A44: FR-EXC-007 | B44: Field verification by the Lighting Supervisor | C44: Reviewer requests; supervisor's findings and photographs recorded on the exception | D44: Request: 200; supervisor notified (NTF-10): yes; task on the supervisor's phone: yes; findings: QA: pole found installed, far end of the junction with 1 photograph(s) | E44: PASS
A45: FR-EXC-010 | B45: Unresolved exceptions age and escalate | C45: Escalation according to the notification rules | D45: After 4 days unresolved: age 4 d, escalation level 1, escalation notices 1 | E45: PASS
A46: FR-EXC-011 | B46: Corrections through an amendment request | C46: Reason, approval by another user, before/after values; original stays visible | D46: Coordinates: HTTP 400 · None · installation.Lat cannot be amended.. Pole ID request AMD/26-27/00001; self-approval HTTP 409 · BR-026 · An amendment must be approved by somebody other than the person who asked for it.; approved by PD Office: pole QA-P7; audit before {"field":"PoleId","value":"QA-P1"} after {"field":"PoleId","value":"QA-P7","amendment":"AMD/26-27/00001"} | E46: PASS
A47: FR-FLD-009 | B47: Original preserved with hash; server-stamped copy | C47: Original photograph unaltered; stamped copy with time, coordinates, accuracy, site, item, officer | D47: Original downloaded byte-for-byte equal to its SHA-256 a6a61e337f6a…: True. Stamped copy: HTTP 200, 475 KB, valid JPEG True. Photograph altered in transit: MissingEvidence, officer told to re-capture (NTF-09) | E47: PASS
A48: FR-FLD-011 | B48: Mock location and clock drift refused and logged | C48: Evidence refused and the attempt logged | D48: Mock location: HTTP 409 · FR-FLD-011 · The phone reported a mock (fake) location. Remove any location-faking app and capture again.. Clock 30 min off: HTTP 409 · FR-FLD-011 · The phone clock is 30 minutes off server time (limit 5). Switch on automatic date and time. | E48: PASS
... A64: FR-SEC-009 | B64: Phone bound to a named user; change of phone re-authorised | C64: Field evidence only from the user's bound phone; a replacement needs approval | D64: Setup required for the officer: True. Before setup test: HTTP 403 · FR-SEC-009 · Finish mobile setup on this phone first (test photograph).. Mock location in setup: refused. Setup: Active. Second phone: AwaitingApproval, submitting from it: HTTP 403 · FR-SEC-009 · This phone is waiting for the administrator to approve it as your new phone.. After approval: Active, old phone session: HTTP 401 | E64: PASS

Sheet Defects
A1: Defects found in the gap analysis — status after remediation
A2: All six were reproduced on 18-09-2026 before the fix; the same probes now run in every acceptance run
A4: ID | B4: Defect | C4: Severity | D4: Fix applied | E4: Probe result in the latest run | F4: Status | G4: Requirements affected | H4: Work package
A5: DF-01 | B5: Every role could read the whole audit trail | C5: High | D5: AuditController: full trail only with the new audit permission; others see their own actions. | E5: officer sees 64 rows, all their own | F5: Fixed | G5: FR-SEC-003, FR-RPT-008 | H5: WP-00
A6: DF-02 | B6: Clock-drift check allowed 65 minutes, not 5 | C6: Medium | D6: Drift measured against the phone clock at synchronisation, at the configured limit. | E6: phone 30 min off: HTTP 409 · FR-FLD-011 · The phone clock is 30 minutes off server time (limit 5). Switch on automatic date and time. | F6: Fixed | G6: FR-FLD-011 | H6: WP-00
A7: DF-03 | B7: A returned item kept its site while in quarantine | C7: Medium | D7: ReturnService clears SiteId on receipt; the return note keeps the site. | E7: returned item carries no site in the store | F7: Fixed | G7: FR-INV-014 | H7: WP-00
A8: DF-04 | B8: A PO line could be re-specified after its article existed | C8: Medium | D8: MasterService refuses changes to category, specification, description and unit once an article exists. | E8: re-specifying the line: HTTP 409 · FR-MD-05 · Line 1 already has article LUM-LED-090W-POQA09181411-001; its category, specification, description and unit can no longer change. Only quantity and rate can. | F8: Fixed | G8: FR-MDM-003, FR-MDM-009 | H8: WP-00
A9: DF-05 | B9: Material could be issued to a site On hold | C9: Medium | D9: IssueService re-checks site and article status at scan and posting. | E9: issue to On-hold site: HTTP 409 · BR-007 · Site SITE-CLAHO-0004 is On hold; material cannot be issued to it. | F9: Fixed | G9: FR-INV-025, FR-MDM-004 | H9: WP-00
A10: DF-06 | B10: Cancelling a requisition ignored data scope | C10: High | D10: RequisitionService.CancelAsync (and DecideAsync) check store and site scope. | E10: out-of-scope cancel: HTTP 403 · scope · Site SITE-N-GTRD-0004 is outside your scope. | F10: Fixed | G10: FR-REQ-007, FR-SEC-003 | H10: WP-00

Sheet Deployment Check
A1: Deployment check — the LAN deployment against the FRD
A2: 18 Sep 2026 · http://172.16.10.184:3001 (office LAN, production build, API on 127.0.0.1:5091)
A4: Ref | B4: FRD requirement | C4: Check performed | D4: Observed on the deployment | E4: Result | F4: Action and owner
A5: §21 TC-01…30 | B5: Acceptance test cases, FRD Section 21 | C5: frd_acceptance.py run through the LAN portal address, as users reach it | D5: First run matched development (14 PASS, 6 PASS*, 5 PARTIAL, 4 NOT BUILT, 1 FAIL; 6 defects). After the 18-09-2026 remediation, rerun on live: 57 checks, 48 PASS, 5 PASS*, 4 PARTIAL (TC-05, TC-27, TC-28, TC-30), 0 NOT BUILT, 0 FAIL; 0 of 6 defects reproduced. | E5: Met | F5: None for the deployment. The 4 partial cases stay on the Gap Register with their follow-up.
A6: FR-SEC-005 | B6: Every action records the client address | C6: Signed in from the LAN address, then read the audit trail | D6: Before the fix every row showed 127.0.0.1: with no IIS / Nginx in front the API only saw the portal. Fixed with deploy/client-ip.cjs, which stamps each request with its own socket address. Retest: LAN sign-in recorded 172.16.10.184; forged X-Real-IP, X-Forwarded-For and Forwarded headers were ignored. | E6: Fixed | F6: Done. The launcher, START-SLIMS.bat, run-web.cmd and the SLIMS-Setup package all load client-ip.cjs.
A7: FR-FLD-008, FR-FLD-010 | B7: GPS latitude, longitude and accuracy captured with each photograph | C7: Asked the browser for a position on the LAN address; then built the SLIMS Field app | D7: A browser refuses GPS on http:// (“Only secure origins are allowed”). Resolved on 18-09-2026 by the SLIMS Field Android app: it reads GPS natively, with Android's mock-location flag, and talks to the LAN server over HTTP, so field capture works without a certificate. | E7: Fixed | F7: Officers install the app from Settings ▸ Mobile Setup. HTTPS is still recommended for transport security (NFR-08).
A8: NFR-08 | B8: TLS 1.2+ for all traffic; refresh cookie never sent without TLS | C8: Inspected the transport and the refresh cookie | D8: Plain HTTP on the LAN; the refresh cookie is httpOnly but not Secure (SecureCookies false, as it must be on HTTP). The release package ships HTTPS proxy configuration and SecureCookies true. | E8: Not met | F8: Same HTTPS step as above, then set SecureCookies true in api\appsettings.Production.json.
A9: NFR-01 | B9: A scan is validated within 2 seconds | C9: 15 QR scans through the LAN portal | D9: Median 17 ms, slowest 40 ms. | E9: Met | F9: Repeat on production data volumes (NFR-11).
A10: NFR-02 | B10: 95 % of screens respond within 3 seconds | C10: 7 pages and 6 data calls, 15 times each | D10: Pages: slowest 32 ms. Data calls: 95th percentile 29–70 ms, slowest 152 ms. | E10: Met | F10: Repeat on production data volumes (NFR-11).
A11: NFR-03 | B11: A year of data reports within 30 seconds | C11: All 15 reports run over 18 Sep 2025 – 18 Sep 2026 | D11: Slowest report (Auto Purchase Indents) 154 ms. | E11: Met | F11: Measured on demonstration data; repeat after data migration.
A12: NFR-11 | B12: ≥ 500,000 labels, ≥ 50,000 sites, ≥ 5 million transactions a year | C12: Not run: needs a generated volume data set | D12: The database holds demonstration data only (80 MB, a few hundred labels). | E12: Not tested | F12: Volume test on a copy of the database before go-live.
A13: NFR-07 | B13: Servers synchronise to a trusted time source | C13: w32tm /query /status on the host | D13: Not synchronised: source is the Local CMOS Clock, last successful sync unspecified. Evidence capture times and the clock-drift check (FR-FLD-011) are measured against this clock. | E13: Not met | F13: IT, as administrator: point Windows Time at the domain controller or time.windows.com and resync.
A14: NFR-09 | B14: 99.5 % availability in operational hours | C14: Checked what restarts SLIMS after a crash or reboot | D14: SLIMS runs as a signed-in user's process. Nothing restarts it after a crash, and nothing starts it after a reboot. PIMRS on the same PC has an auto-start entry; SLIMS has none yet. | E14: Not met | F14: Add start_slims.pyw --watch to Windows Startup (awaiting approval), or install as a service with 3-install-as-service on a server.
A15: NFR-10 | B15: Backup: RPO ≤ 15 minutes, RTO ≤ 4 hours; database and evidence backed up together | C15: Read backup history and recovery model from SQL Server | D15: The Slims database has never been backed up, and its recovery model is SIMPLE, so point-in-time recovery (needed for a 15-minute RPO) is impossible. The evidence uploads folder has no backup either. | E15: Not met | F15: Switch Slims to FULL recovery; schedule a nightly full backup, log backups every 15 minutes and an uploads copy; test a restore.
... A20: Portability | B20: Install on another PC or server | C20: SLIMS-Setup run against an empty database on spare ports | D20: Database created and seeded in 4 seconds; first sysadmin sign-in set the password; the bundled node.exe served all pages and assets and proxied the API. Test database removed afterwards. | E20: Met | F20: None.

Sheet Rules & Reports
A1: Business rules, reports and notifications
A2: Coverage of FRD Sections 10, 14 and 15.1
A4: Business rules (FRD Section 10)
A5: Rule | B5: Statement | C5: Status | D5: Evidence
A6: BR-01 | B6: No PO / reference → no standard receipt. | C6: Met | D6: Posting without a PO refused (TC-02).
A7: BR-02 | B7: No valid item / QR → no controlled stock movement. | C7: Met | D7: Forged / unregistered labels refused (TC-03).
A8: BR-03 | B8: No approved requisition → no issue to site. | C8: Met | D8: Issue refused before approval (TC-12).
A9: BR-04 | B9: An issue must identify a registered Site ID. | C9: Met | D9: Requisition needs a registered site ID (TC-07).
A10: BR-05 | B10: Installation requires before and after evidence. | C10: Met | D10: Refused without AFTER photo (TC-16).
A11: BR-06 | B11: A GPS mismatch creates an exception; it never completes an installation. | C11: Met | D11: Mismatch held for review (TC-19).
A12: BR-07 | B12: An out-of-order return requires a QR scan and a condition / reason. | C12: Met | D12: Reason codes and consignment condition recorded at receipt.
A13: BR-08 | B13: Every stock movement updates the item ledger. | C13: Met | D13: Quantity ledger (StockMovement) with reconciliation.
A14: BR-09 | B14: Every exception or override requires authorised review and an audit trail. | C14: Partially met | D14: Exceptions, disposal, adjustments and amendments need approval; over-receipt exception route still missing.
A15: BR-10 | B15: A site must exist in the system before material is issued to it. | C15: Met | D15: Site must exist before requisition and issue.
A16: BR-11 | B16: A QR identifier is unique system-wide and never reused. | C16: Met | D16: Unique, never reused (TC-04).
... A38: BR-33 | B38: Removed items must reach a store within the configured return period. | C38: Met | D38: Escalation of work not actioned.
A40: Report catalogue (FRD Section 15.1)
A41: Report | B41: Name | C41: Status | D41: Current build
A42: RPT-01 | B42: PO receipt register | C42: Met | D42: Report “Goods Receipt / Inward Register”.
A43: RPT-02 | B43: Discrepancy & over-receipt register | C43: Partially met | D43: Discrepancies only; no over-receipt exceptions.
A44: RPT-03 | B44: Stock position | C44: Partially met | D44: Stock screen; no export.
A45: RPT-04 | B45: Stock reconciliation | C45: Met | D45: Stock Reconciliation report (TC-29).
A46: RPT-05 | B46: Requisition status & turnaround | C46: Met | D46: Requisition status with turnaround hours.
A47: RPT-06 | B47: Issue register & gate passes | C47: Met | D47: Issue register with gate passes and acknowledgement.
A48: RPT-07 | B48: Site installation report | C48: Met | D48: Installation activity report.
A49: RPT-08 | B49: GPS validation report | C49: Met | D49: Distance, allowed limit, accuracy and status in the installation report.
A50: RPT-09 | B50: Evidence register | C50: Met | D50: Evidence Register with SHA-256, capture and sync time, device.
A51: RPT-10 | B51: Exception register & ageing | C51: Met | D51: Exception report with age, escalation level and field verification.
A52: RPT-11 | B52: Out-of-order & return report | C52: Met | D52: Out-of-order and return report.
... A61: RPT-20 | B61: Audit trail extract | C61: Partially met | D61: Audit screen scoped (DF-01 fixed); no export.
A63: Notifications (FRD Section 14)
A64: ID | B64: Event → recipients | C64: Status | D64: Current build
A65: NTF-01 | B65: Requisition submitted → Approving Officer | C65: Met | D65: Sent by NotificationService; e-mail / SMS copies where configured
A66: NTF-02 | B66: Requisition approved → Lighting Supervisor; issuing Store / Warehouse Officer | C66: Met | D66: Sent by NotificationService; e-mail / SMS copies where configured
A67: NTF-03 | B67: Requisition rejected → Lighting Supervisor | C67: Met | D67: Sent by NotificationService; e-mail / SMS copies where configured
A68: NTF-04 | B68: Reservation lapsing in 1 day / lapsed → Lighting Supervisor; Store / Warehouse Officer | C68: Met | D68: Sent by NotificationService; e-mail / SMS copies where configured
A69: NTF-05 | B69: Issue completed (gate pass) → Lighting Supervisor; Lighting Officer of the site | C69: Met | D69: Sent by NotificationService; e-mail / SMS copies where configured
A70: NTF-06 | B70: Issue not acknowledged → Lighting Officer; Lighting Supervisor | C70: Met | D70: Sent by NotificationService; e-mail / SMS copies where configured
A71: NTF-07 | B71: Installation pending — issued but not installed → Lighting Officer; Lighting Supervisor | C71: Met | D71: Sent by NotificationService; e-mail / SMS copies where configured
A72: NTF-08 | B72: GPS exception raised → Project / Monitoring Officer; copy Lighting Supervisor | C72: Met | D72: Sent by NotificationService; e-mail / SMS copies where configured
...

Sheet Remediation Plan
A1: Remediation plan — work packages in waves
A2: Est. person-days come from the size table on the Legend sheet; ‘Open requirements addressed’ counts Gap Register rows not yet Met that the package addresses
A4: WP | B4: Wave | C4: Work package | D4: Scope | E4: Size | F4: Est. person-days | G4: Open requirements addressed | H4: Depends on | I4: Items covered
A5: WP-00 | B5: Wave 0 — Fix now | C5: Defect fixes | D5: DF-01 audit scope, DF-02 clock check, DF-03 return clears site, DF-04 lock PO lines with articles, DF-05 re-check site and article status at issue, DF-06 scope on cancel | E5: M | F5: =INDEX(Legend!$B$29:$B$32,MATCH(E5,Legend!$A$29:$A$32,0)) -> 5 | G5: =COUNTIFS('Gap Register'!$K$5:$K$126,A5,'Gap Register'!$G$5:$G$126,"<>Met") -> 5 | H5: — | I5: DF-01, DF-02, DF-03, DF-04, DF-05, DF-06; FR-MDM-003, FR-MDM-004, FR-MDM-009, FR-INV-014, FR-INV-025, FR-REQ-007, FR-SEC-003
A6: WP-01 | B6: Wave 1 — Align | C6: Role model & approval matrix | D6: Approving Officer, Project / Monitoring Officer, Management roles; value-band approval with escalation; reason-code lists; role administration | E6: L | F6: =INDEX(Legend!$B$29:$B$32,MATCH(E6,Legend!$A$29:$A$32,0)) -> 10 | G6: =COUNTIFS('Gap Register'!$K$5:$K$126,A6,'Gap Register'!$G$5:$G$126,"<>Met") -> 4 | H6: D-02, D-03 | I6: FR-MDM-019, FR-REQ-005, FR-REQ-010, FR-SEC-002, FR-SEC-008
A7: WP-02 | B7: Wave 1 — Align | C7: Store locations & put-away | D7: Store → Rack → Shelf → Bin; Receiving and Repair location types; scan put-away; bin moves | E7: L | F7: =INDEX(Legend!$B$29:$B$32,MATCH(E7,Legend!$A$29:$A$32,0)) -> 10 | G7: =COUNTIFS('Gap Register'!$K$5:$K$126,A7,'Gap Register'!$G$5:$G$126,"<>Met") -> 3 | H7: D-01 | I7: FR-MDM-012, FR-MDM-013, FR-INV-010, FR-INV-011, FR-INV-012
A8: WP-03 | B8: Wave 1 — Align | C8: Receipt controls | D8: Condition and per-item rejection; automatic discrepancy notes; over-receipt exception; re-print reason; VAL-INV-001 message | E8: M | F8: =INDEX(Legend!$B$29:$B$32,MATCH(E8,Legend!$A$29:$A$32,0)) -> 5 | G8: =COUNTIFS('Gap Register'!$K$5:$K$126,A8,'Gap Register'!$G$5:$G$126,"<>Met") -> 3 | H8: D-04; WP-01 | I8: FR-MDM-008, FR-INV-003, FR-INV-004, FR-INV-005, FR-INV-006
A9: WP-04 | B9: Wave 1 — Align | C9: Requisition completion | D9: Priority and justification; draft editing; revise and resubmit; reservation lapse | E9: M | F9: =INDEX(Legend!$B$29:$B$32,MATCH(E9,Legend!$A$29:$A$32,0)) -> 5 | G9: =COUNTIFS('Gap Register'!$K$5:$K$126,A9,'Gap Register'!$G$5:$G$126,"<>Met") -> 3 | H9: D-10 | I9: FR-REQ-001, FR-REQ-004, FR-REQ-013, FR-REQ-014
A10: WP-05 | B10: Wave 1 — Align | C10: Evidence validation & exception model | D10: Both-photo validation; Valid / Location Exception / Missing Evidence with review status; Rejected outcome; field verification; unified queue with filters | E10: L | F10: =INDEX(Legend!$B$29:$B$32,MATCH(E10,Legend!$A$29:$A$32,0)) -> 10 | G10: =COUNTIFS('Gap Register'!$K$5:$K$126,A10,'Gap Register'!$G$5:$G$126,"<>Met") -> 6 | H10: D-02; WP-01 | I10: FR-FLD-004, FR-EXC-001, FR-EXC-002, FR-EXC-004, FR-EXC-005, FR-EXC-006, FR-EXC-007
A11: WP-06 | B11: Wave 1 — Align | C11: Returns completion | D11: Usable route; condition and photos on report; history on receipt; replaced-item field | E11: M | F11: =INDEX(Legend!$B$29:$B$32,MATCH(E11,Legend!$A$29:$A$32,0)) -> 5 | G11: =COUNTIFS('Gap Register'!$K$5:$K$126,A11,'Gap Register'!$G$5:$G$126,"<>Met") -> 4 | H11: D-06 | I11: FR-INV-030, FR-INV-031, FR-INV-032, FR-INV-033, FR-INV-039
